<?xml version="1.0"?>
<robot name="physics">
    <link name="slideBar">
        <visual>
        <geometry>
            <box size="100 0.05 0.05"/>
        </geometry>
        <origin xyz="0 0 0"/>
        <material name="green">
            <color rgba="0 0.8 .8 1"/>
        </material>
        </visual>
        <inertial>
        <mass value="1.0"/>
        <inertia ixx="1.0" ixy="0.0" ixz="0.0" iyy="1.0" iyz="0.0" izz="1.0"/>
        </inertial>
    </link>
    <link name="cart">
        <visual>
        <geometry>
            <box size="0.25 0.1 0.1"/>
        </geometry>
        <origin xyz="0 0 0"/>
        <material name="blue">
            <color rgba="0 0 .8 1"/>
        </material>
        </visual>
        <collision>
        <geometry>
            <box size="0.25 0.1 0.1"/>
        </geometry>
        <origin xyz="0 0 0"/>
        </collision>
            <inertial>
            <mass value="1.0"/>
            <inertia ixx="0.001666666666666667" ixy="0.0" ixz="0.0" iyy="0.006041666666666667" iyz="0.0" izz="0.006041666666666667"/>
            <!-- <inertia ixx="1.0" ixy="0.0" ixz="0.0" iyy="1.0" iyz="0.0" izz="1.0"/> -->
        </inertial>
    </link>
    <link name="pole">
        <visual>
            <geometry>
                <box size="0.05 0.05 1.0"/>	
            </geometry>
            <origin rpy="0 0 0" xyz="0 0 0.5"/>
            <material name="gray">
                <color rgba="0.7 0.7 0.7 1"/>
            </material>
        </visual>
        <inertial>
            <origin xyz="0 0 0.5"/>
            <!-- <origin xyz="0.6 0 0.62"/> -->
            <!-- <origin xyz="-0.6 0 0.38"/> -->
            <mass value="1.0"/>
            <inertia ixx="1.0" ixy="0.0" ixz="0.0" iyy="1.0" iyz="0.0" izz="1.0"/>
        </inertial>
        <collision>
            <geometry>
                <box size="0.05 0.05 1.0"/>	
            </geometry>
            <origin rpy="0 0 0" xyz="0 0 0.5"/>
        </collision>
    </link>
    <link name="world" />

    <joint name="slideBar_joint" type="fixed">
        <origin xyz="0 0 0" rpy="0 0 0" />
        <parent link="world" />
        <child link="slideBar" />
    </joint>
    <joint name="slider_to_cart" type="prismatic">
        <axis xyz="1 0 0"/>
        <origin xyz="0.0 0.0 0.0"/>
        <parent link="slideBar"/>
        <child link="cart"/>
        <limit effort="1000.0" lower="-15" upper="15" velocity="5"/>
    </joint>
    <joint name="cart_to_pole" type="continuous">
        <axis xyz="0 1 0"/>
        <origin xyz="0.0 0.0 0"/>
        <parent link="cart"/>
        <child link="pole"/>
    </joint>

</robot>