<?xml version="0.0" ?>
<robot name="jumper_inverted">

	<link name="head">
		<inertial>
			<!-- mass, inertia will be overwritten-->
			<mass value="1"/>
			<inertia ixx="1" ixy="0" ixz="0" iyy="1" iyz="0" izz="1"/>
		</inertial>
		<visual>
			<geometry>
				<box size="0.12 0.14 0.14"/>
			</geometry>
		</visual>
	</link>

	<link name="torso">
		<inertial>
			<!-- mass, inertia will be overwritten-->
			<mass value="1"/>
			<inertia ixx="1" ixy="0" ixz="0" iyy="1" iyz="0" izz="1"/>
		</inertial>
		<visual>
			<geometry>
				<box size="0.12 0.32 0.20"/>
			</geometry>
		</visual>
	</link>

	<link name="lwaist">
		<inertial>
			<!-- mass, inertia will be overwritten-->
			<mass value="1"/>
			<inertia ixx="1" ixy="0" ixz="0" iyy="1" iyz="0" izz="1"/>
		</inertial>
		<visual>
			<geometry>
				<box size="0.12 0.18 0.12"/>
			</geometry>
		</visual>
	</link>

	<link name="pelvis">
		<inertial>
			<origin rpy="0.00000 -0.00000 0.00000" xyz="0.00000 0.10000 0.10000"/>
			<!-- mass, inertia will be overwritten-->
			<mass value="1"/>
			<inertia ixx="1" ixy="0" ixz="0" iyy="1" iyz="0" izz="1"/>
		</inertial>
		<visual>
			<origin rpy="0.00000 -0.00000 0.00000" xyz="0.00000 0.10000 0.10000"/>
			<geometry>
				<box size="0.14 0.24 0.18"/>
			</geometry>
		</visual>
	</link>

	<link name="right_thigh">
		<inertial>
			<origin rpy="0.0 -0.00000 0.00000" xyz="0.00000 0.0000 0.24000"/>
			<!-- mass, inertia will be overwritten-->
			<mass value="1"/>
			<inertia ixx="1" ixy="0" ixz="0" iyy="1" iyz="0" izz="1"/>
		</inertial>
		<visual>
			<origin rpy="0.0 -0.00000 0.00000" xyz="0.00000 0.0000 0.24000"/>
			<geometry>
				<box size="0.14 0.14 0.44"/>
			</geometry>
		</visual>
	</link>

	<link name="right_shin">
		<inertial>
			<origin rpy="0.0 0.00000 0.0" xyz="0.00000 0.00000 0.2000"/>
			<!-- mass, inertia will be overwritten-->
			<mass value="1"/>
			<inertia ixx="1" ixy="0" ixz="0" iyy="1" iyz="0" izz="1"/>
		</inertial>
		<visual>
			<origin rpy="0.0 0.00000 0.0" xyz="0.00000 0.00000 0.2000"/>
			<geometry>
				<box size="0.12 0.12 0.4"/>
			</geometry>
		</visual>
	</link>

	<link name="right_foot">
		<inertial>
			<origin rpy="0.00000 -0.00000 0.00000" xyz="-0.1700 0.000 0.00000"/>
			<!-- mass, inertia will be overwritten-->
			<mass value="1"/>
			<inertia ixx="1" ixy="0" ixz="0" iyy="1" iyz="0" izz="1"/>
		</inertial>
		<visual>
			<origin rpy="0.00000 -0.00000 0.00000" xyz="-0.1700 0.000 0.00000"/>
			<geometry>
				<box size="0.20 0.14 0.05"/>
			</geometry>
		</visual>
	</link>

	<link name="right_toe">
		<inertial>
			<!-- mass, inertia will be overwritten-->
			<mass value="1"/>
			<inertia ixx="1" ixy="0" ixz="0" iyy="1" iyz="0" izz="1"/>
		</inertial>
		<visual>
			<geometry>
				<box size="0.12 0.14 0.05"/>
			</geometry>
		</visual>
	</link>

	<joint name="right_toe" type="continuous">
		<parent link="right_toe"/>
		<child link="right_foot"/>
		<dynamics damping="0.2" friction="0.0001"/>
		<origin rpy="0.00000 0.00000 0.00000" xyz="-0.035000 0.00000 0.00000"/>
		<axis xyz="0.00000 1.00000 0.00000"/>
<!--		<limit lower="-0.1" upper="1.4971975512"/>-->
	</joint>

	<joint name="right_ankle" type="continuous">
		<parent link="right_foot"/>
		<child link="right_shin"/>
		<dynamics damping="0.2" friction="0.0001"/>
		<origin rpy="0.00000 -0.00000 0.00000" xyz="-0.2000 0.00000 0.00000"/>
		<axis xyz="0.00000 -1.00000 0.00000"/>
<!--		<limit lower="-1.0971975512" upper="1.0971975512"/>-->
	</joint>

	<joint name="right_knee" type="continuous">
		<parent link="right_shin"/>
		<child link="right_thigh"/>
		<dynamics damping="0.2" friction="0.0001"/>
		<origin rpy="0.00000 -0.00000 0.00000" xyz="0.00000 0.0000 0.400"/>
		<axis xyz="0.00000 -1.00000 0.00000"/>
<!--		<limit lower="-0.1" upper="2.8"/>-->
	</joint>

	<joint name="right_hip_y" type="continuous">
		<parent link="right_thigh"/>
		<child link="pelvis"/>
		<dynamics damping="0.2" friction="0.0001"/>
		<origin rpy="0.00000 -0.00000 0.00000" xyz="0.00000 0.0000 0.480"/>
		<axis xyz="0.00000 1.00000 0.00000"/>
<!--		<limit lower="-1.57" upper="2.2"/>-->
	</joint>

    <joint name="abdomen_2" type="fixed">
		<parent link="pelvis"/>
		<child link="lwaist"/>
		<origin rpy="0.00000 -0.0000 0.00000" xyz="0.0000 0.10000 0.26500"/>
		<axis xyz="0.00000 0.00000 0.00000"/>
	</joint>

	<joint name="abdomen" type="fixed">
		<parent link="lwaist"/>
		<child link="torso"/>
		<origin rpy="0.00000 -0.00000 0.00000" xyz="0.00000 0.00000 0.18500"/>
		<axis xyz="0.00000 0.00000 0.00000"/>
	</joint>

	<joint name="jointfix_head" type="fixed">
		<parent link="torso"/>
		<child link="head"/>
		<origin rpy="0.00000 -0.00000 0.00000" xyz="0.00000 0.00000 0.25"/>
		<axis xyz="0.00000 0.00000 0.00000"/>
	</joint>
</robot>
